<?xml version="1.0" ?>
<!-- =================================================================================== -->
<!-- |    This document was manually stitched together based on kuka_bord.urdf and the | -->
<!-- |    iiwa7.urdf                                                                   | -->
<!-- =================================================================================== -->
<!-- top level -->
<robot name="iiwa7">  
  <!-- Matrials -->
  <material name="steel_satin">
    <color rgba="0.6274509803921569 0.6274509803921569 0.6274509803921569 1.0"/>
  </material>
  
  <!-- world link -->
  <link name="world"/>  
  
  <!-- Table link -->
  <link name="base_link">
    <inertial>
      <origin rpy="0 0 0" xyz="0.47511520643410643 0.9340356249199337 1.753635248949686"/>
      <mass value="1382.7919279449686"/>
      <inertia ixx="1994.27355" ixy="-0.365832" ixz="-0.552572" iyy="2787.103818" iyz="-145.275916" izz="966.579181"/>
    </inertial>
    <visual>
      <origin rpy="0 0 0" xyz="0 0 0"/>
      <geometry>
        <mesh filename="package://kuka_bord_description/meshes/table_meshes/visual/base_link.stl" scale="0.001 0.001 0.001"/>
      </geometry>
      <material name="steel_satin"/>
    </visual>
    <collision>
      <origin rpy="0 0 0" xyz="0 0 0"/>
      <geometry>
        <mesh filename="package://kuka_bord_description/meshes/table_meshes/collision/base_link_low_polly.stl" scale="0.001 0.001 0.001"/>
      </geometry>
    </collision>
  </link>
  
  <!-- 1 iiwa7 link-->
  <link name="link_0">
    <inertial>
      <origin rpy="0 0 0" xyz="-0.012857 0.0 0.069964"/>
      <mass value="4.855658"/>
      <inertia ixx="0.017839" ixy="0.0" ixz="0.000781" iyy="0.022294" iyz="0.0" izz="0.021334"/>
    </inertial>
    <visual>
      <origin rpy="0 0 0" xyz="0 0 0"/>
      <geometry>
        <mesh filename="package://kuka_bord_description/meshes/iiwa7_meshes/visual/link_0.dae"/>
      </geometry>
    </visual>
    <collision>
      <origin rpy="0 0 0" xyz="0 0 0"/>
      <geometry>
        <mesh filename="package://kuka_bord_description/meshes/iiwa7_meshes/collision/link_0.stl"/>
      </geometry>
    </collision>
  </link>
  <joint name="A1" type="revolute">
    <origin rpy="0 0 0" xyz="0.0 0.0 0.1475"/>
    <parent link="link_0"/>
    <child link="link_1"/>
    <axis xyz="0.0 0.0 1.0"/>
    <limit effort="200" lower="-2.9670597283903604" upper="2.9670597283903604" velocity="1.710422666954443"/>
    <dynamics damping="10.0" friction="0.1"/>
  </joint>
  <link name="link_1">
    <inertial>
      <origin rpy="0 0 0" xyz="0.0 -0.034819 0.123299"/>
      <mass value="3.394011"/>
      <inertia ixx="0.021383" ixy="0.0" ixz="0.0" iyy="0.020403" iyz="0.003797" izz="0.007563"/>
    </inertial>
    <visual>
      <origin rpy="0 0 0" xyz="0.0 0.0 -0.1475"/>
      <geometry>
        <mesh filename="package://kuka_bord_description/meshes/iiwa7_meshes/visual/link_1.dae"/>
      </geometry>
    </visual>
    <collision>
      <origin rpy="0 0 0" xyz="0.0 0.0 -0.1475"/>
      <geometry>
        <mesh filename="package://kuka_bord_description/meshes/iiwa7_meshes/collision/link_1.stl"/>
      </geometry>
    </collision>
  </link>
  <joint name="A2" type="revolute">
    <origin rpy="0 0 0" xyz="0.0 -0.0105 0.1925"/>
    <parent link="link_1"/>
    <child link="link_2"/>
    <axis xyz="0.0 1.0 0.0"/>
    <limit effort="200" lower="-2.0943951023931953" upper="2.0943951023931953" velocity="1.710422666954443"/>
    <dynamics damping="10.0" friction="0.1"/>
  </joint>
  <link name="link_2">
    <inertial>
      <origin rpy="0 0 0" xyz="0.0 0.039793 0.086944"/>
      <mass value="4.031991"/>
      <inertia ixx="0.031697" ixy="0.0" ixz="0.0" iyy="0.03008" iyz="0.005889" izz="0.009666"/>
    </inertial>
    <visual>
      <origin rpy="0 0 0" xyz="0.0 0.0105 -0.34"/>
      <geometry>
        <mesh filename="package://kuka_bord_description/meshes/iiwa7_meshes/visual/link_2.dae"/>
      </geometry>
    </visual>
    <collision>
      <origin rpy="0 0 0" xyz="0.0 0.0105 -0.34"/>
      <geometry>
        <mesh filename="package://kuka_bord_description/meshes/iiwa7_meshes/collision/link_2.stl"/>
      </geometry>
    </collision>
  </link>
  <joint name="A3" type="revolute">
    <origin rpy="0 0 0" xyz="0.0 0.0105 0.2075"/>
    <parent link="link_2"/>
    <child link="link_3"/>
    <axis xyz="0.0 0.0 1.0"/>
    <limit effort="200" lower="-2.9670597283903604" upper="2.9670597283903604" velocity="1.7453292519943295"/>
    <dynamics damping="10.0" friction="0.1"/>
  </joint>
  <link name="link_3">
    <inertial>
      <origin rpy="0 0 0" xyz="0.0 0.034819 0.123299"/>
      <mass value="3.394011"/>
      <inertia ixx="0.021383" ixy="0.0" ixz="0.0" iyy="0.020403" iyz="-0.003797" izz="0.007563"/>
    </inertial>
    <visual>
      <origin rpy="0 0 0" xyz="0.0 0.0 -0.5475"/>
      <geometry>
        <mesh filename="package://kuka_bord_description/meshes/iiwa7_meshes/visual/link_3.dae"/>
      </geometry>
    </visual>
    <collision>
      <origin rpy="0 0 0" xyz="0.0 0.0 -0.5475"/>
      <geometry>
        <mesh filename="package://kuka_bord_description/meshes/iiwa7_meshes/collision/link_3.stl"/>
      </geometry>
    </collision>
  </link>
  <joint name="A4" type="revolute">
    <origin rpy="0 0 0" xyz="0.0 0.0105 0.1925"/>
    <parent link="link_3"/>
    <child link="link_4"/>
    <axis xyz="0.0 -1.0 0.0"/>
    <limit effort="200" lower="-2.0943951023931953" upper="2.0943951023931953" velocity="2.2689280275926285"/>
    <dynamics damping="10.0" friction="0.1"/>
  </joint>
  <link name="link_4">
    <inertial>
      <origin rpy="0 0 0" xyz="0.0 -0.039793 0.086944"/>
      <mass value="4.031989"/>
      <inertia ixx="0.031695" ixy="0.0" ixz="0.0" iyy="0.030079" iyz="-0.005889" izz="0.009665"/>
    </inertial>
    <visual>
      <origin rpy="0 0 0" xyz="0.0 -0.0105 -0.74"/>
      <geometry>
        <mesh filename="package://kuka_bord_description/meshes/iiwa7_meshes/visual/link_4.dae"/>
      </geometry>
    </visual>
    <collision>
      <origin rpy="0 0 0" xyz="0.0 -0.0105 -0.74"/>
      <geometry>
        <mesh filename="package://kuka_bord_description/meshes/iiwa7_meshes/collision/link_4.stl"/>
      </geometry>
    </collision>
  </link>
  <joint name="A5" type="revolute">
    <origin rpy="0 0 0" xyz="0.0 -0.0105 0.2075"/>
    <parent link="link_4"/>
    <child link="link_5"/>
    <axis xyz="0.0 0.0 1.0"/>
    <limit effort="200" lower="-2.9670597283903604" upper="2.9670597283903604" velocity="2.443460952792061"/>
    <dynamics damping="10.0" friction="0.1"/>
  </joint>
  <link name="link_5">
    <inertial>
      <origin rpy="0 0 0" xyz="0.0 -0.029824 0.076267"/>
      <mass value="1.529239"/>
      <inertia ixx="0.008485" ixy="0.0" ixz="0.0" iyy="0.007136" iyz="0.002806" izz="0.003848"/>
    </inertial>
    <visual>
      <origin rpy="0 0 0" xyz="0.0 0.0 -0.9475"/>
      <geometry>
        <mesh filename="package://kuka_bord_description/meshes/iiwa7_meshes/visual/link_5.dae"/>
      </geometry>
    </visual>
    <collision>
      <origin rpy="0 0 0" xyz="0.0 0.0 -0.9475"/>
      <geometry>
        <mesh filename="package://kuka_bord_description/meshes/iiwa7_meshes/collision/link_5.stl"/>
      </geometry>
    </collision>
  </link>
  <joint name="A6" type="revolute">
    <origin rpy="0 0 0" xyz="0.0 -0.0707 0.1925"/>
    <parent link="link_5"/>
    <child link="link_6"/>
    <axis xyz="0.0 1.0 0.0"/>
    <limit effort="200" lower="-2.0943951023931953" upper="2.0943951023931953" velocity="3.141592653589793"/>
    <dynamics damping="10.0" friction="0.1"/>
  </joint>
  <link name="link_6">
    <inertial>
      <origin rpy="0 0 0" xyz="0.0 0.07102 0.00495"/>
      <mass value="2.403626"/>
      <inertia ixx="0.007067" ixy="0.0" ixz="0.0" iyy="0.006804" iyz="0.000311" izz="0.004629"/>
    </inertial>
    <visual>
      <origin rpy="0 0 0" xyz="0.0 0.0707 -1.14"/>
      <geometry>
        <mesh filename="package://kuka_bord_description/meshes/iiwa7_meshes/visual/link_6.dae"/>
      </geometry>
    </visual>
    <collision>
      <origin rpy="0 0 0" xyz="0.0 0.0707 -1.14"/>
      <geometry>
        <mesh filename="package://kuka_bord_description/meshes/iiwa7_meshes/collision/link_6.stl"/>
      </geometry>
    </collision>
  </link>
  <joint name="A7" type="revolute">
    <origin rpy="0 0 0" xyz="0.0 0.0707 0.091"/>
    <parent link="link_6"/>
    <child link="link_7"/>
    <axis xyz="0.0 0.0 1.0"/>
    <limit effort="200" lower="-3.0543261909900763" upper="3.0543261909900763" velocity="3.141592653589793"/>
    <dynamics damping="10.0" friction="0.1"/>
  </joint>
  <link name="link_7">
    <inertial>
      <origin rpy="0 0 0" xyz="3.0000e-06 -2.0000e-06 1.3782e-02"/>
      <mass value="0.259474"/>
      <inertia ixx="0.000171" ixy="0.0" ixz="0.0" iyy="0.000171" iyz="0.0" izz="0.000299"/>
    </inertial>
    <visual>
      <origin rpy="0 0 0" xyz="0.0 0.0 -1.231"/>
      <geometry>
        <mesh filename="package://kuka_bord_description/meshes/iiwa7_meshes/visual/link_7.dae"/>
      </geometry>
    </visual>
    <collision>
      <origin rpy="0 0 0" xyz="0.0 0.0 -1.231"/>
      <geometry>
        <mesh filename="package://kuka_bord_description/meshes/iiwa7_meshes/collision/link_7.stl"/>
      </geometry>
    </collision>
  </link>
  <joint name="joint_ee" type="fixed">
    <parent link="link_7"/>
    <child link="link_ee"/>
    <origin rpy="0 0 0" xyz="0 0 0.035"/>
  </joint>
  <link name="link_ee">
        </link>

<!-- 2 iiwa7 link-->
  <link name="2_link_0">
    <inertial>
      <origin rpy="0 0 0" xyz="-0.012857 0.0 0.069964"/>
      <mass value="4.855658"/>
      <inertia ixx="0.017839" ixy="0.0" ixz="0.000781" iyy="0.022294" iyz="0.0" izz="0.021334"/>
    </inertial>
    <visual>
      <origin rpy="0 0 0" xyz="0 0 0"/>
      <geometry>
        <mesh filename="package://kuka_bord_description/meshes/iiwa7_meshes/visual/link_0.dae"/>
      </geometry>
    </visual>
    <collision>
      <origin rpy="0 0 0" xyz="0 0 0"/>
      <geometry>
        <mesh filename="package://kuka_bord_description/meshes/iiwa7_meshes/collision/link_0.stl"/>
      </geometry>
    </collision>
  </link>
  <joint name="2_A1" type="revolute">
    <origin rpy="0 0 0" xyz="0.0 0.0 0.1475"/>
    <parent link="2_link_0"/>
    <child link="2_link_1"/>
    <axis xyz="0.0 0.0 1.0"/>
    <limit effort="200" lower="-2.9670597283903604" upper="2.9670597283903604" velocity="1.710422666954443"/>
    <dynamics damping="10.0" friction="0.1"/>
  </joint>
  <link name="2_link_1">
    <inertial>
      <origin rpy="0 0 0" xyz="0.0 -0.034819 0.123299"/>
      <mass value="3.394011"/>
      <inertia ixx="0.021383" ixy="0.0" ixz="0.0" iyy="0.020403" iyz="0.003797" izz="0.007563"/>
    </inertial>
    <visual>
      <origin rpy="0 0 0" xyz="0.0 0.0 -0.1475"/>
      <geometry>
        <mesh filename="package://kuka_bord_description/meshes/iiwa7_meshes/visual/link_1.dae"/>
      </geometry>
    </visual>
    <collision>
      <origin rpy="0 0 0" xyz="0.0 0.0 -0.1475"/>
      <geometry>
        <mesh filename="package://kuka_bord_description/meshes/iiwa7_meshes/collision/link_1.stl"/>
      </geometry>
    </collision>
  </link>
  <joint name="2_A2" type="revolute">
    <origin rpy="0 0 0" xyz="0.0 -0.0105 0.1925"/>
    <parent link="2_link_1"/>
    <child link="2_link_2"/>
    <axis xyz="0.0 1.0 0.0"/>
    <limit effort="200" lower="-2.0943951023931953" upper="2.0943951023931953" velocity="1.710422666954443"/>
    <dynamics damping="10.0" friction="0.1"/>
  </joint>
  <link name="2_link_2">
    <inertial>
      <origin rpy="0 0 0" xyz="0.0 0.039793 0.086944"/>
      <mass value="4.031991"/>
      <inertia ixx="0.031697" ixy="0.0" ixz="0.0" iyy="0.03008" iyz="0.005889" izz="0.009666"/>
    </inertial>
    <visual>
      <origin rpy="0 0 0" xyz="0.0 0.0105 -0.34"/>
      <geometry>
        <mesh filename="package://kuka_bord_description/meshes/iiwa7_meshes/visual/link_2.dae"/>
      </geometry>
    </visual>
    <collision>
      <origin rpy="0 0 0" xyz="0.0 0.0105 -0.34"/>
      <geometry>
        <mesh filename="package://kuka_bord_description/meshes/iiwa7_meshes/collision/link_2.stl"/>
      </geometry>
    </collision>
  </link>
  <joint name="2_A3" type="revolute">
    <origin rpy="0 0 0" xyz="0.0 0.0105 0.2075"/>
    <parent link="2_link_2"/>
    <child link="2_link_3"/>
    <axis xyz="0.0 0.0 1.0"/>
    <limit effort="200" lower="-2.9670597283903604" upper="2.9670597283903604" velocity="1.7453292519943295"/>
    <dynamics damping="10.0" friction="0.1"/>
  </joint>
  <link name="2_link_3">
    <inertial>
      <origin rpy="0 0 0" xyz="0.0 0.034819 0.123299"/>
      <mass value="3.394011"/>
      <inertia ixx="0.021383" ixy="0.0" ixz="0.0" iyy="0.020403" iyz="-0.003797" izz="0.007563"/>
    </inertial>
    <visual>
      <origin rpy="0 0 0" xyz="0.0 0.0 -0.5475"/>
      <geometry>
        <mesh filename="package://kuka_bord_description/meshes/iiwa7_meshes/visual/link_3.dae"/>
      </geometry>
    </visual>
    <collision>
      <origin rpy="0 0 0" xyz="0.0 0.0 -0.5475"/>
      <geometry>
        <mesh filename="package://kuka_bord_description/meshes/iiwa7_meshes/collision/link_3.stl"/>
      </geometry>
    </collision>
  </link>
  <joint name="2_A4" type="revolute">
    <origin rpy="0 0 0" xyz="0.0 0.0105 0.1925"/>
    <parent link="2_link_3"/>
    <child link="2_link_4"/>
    <axis xyz="0.0 -1.0 0.0"/>
    <limit effort="200" lower="-2.0943951023931953" upper="2.0943951023931953" velocity="2.2689280275926285"/>
    <dynamics damping="10.0" friction="0.1"/>
  </joint>
  <link name="2_link_4">
    <inertial>
      <origin rpy="0 0 0" xyz="0.0 -0.039793 0.086944"/>
      <mass value="4.031989"/>
      <inertia ixx="0.031695" ixy="0.0" ixz="0.0" iyy="0.030079" iyz="-0.005889" izz="0.009665"/>
    </inertial>
    <visual>
      <origin rpy="0 0 0" xyz="0.0 -0.0105 -0.74"/>
      <geometry>
        <mesh filename="package://kuka_bord_description/meshes/iiwa7_meshes/visual/link_4.dae"/>
      </geometry>
    </visual>
    <collision>
      <origin rpy="0 0 0" xyz="0.0 -0.0105 -0.74"/>
      <geometry>
        <mesh filename="package://kuka_bord_description/meshes/iiwa7_meshes/collision/link_4.stl"/>
      </geometry>
    </collision>
  </link>
  <joint name="2_A5" type="revolute">
    <origin rpy="0 0 0" xyz="0.0 -0.0105 0.2075"/>
    <parent link="2_link_4"/>
    <child link="2_link_5"/>
    <axis xyz="0.0 0.0 1.0"/>
    <limit effort="200" lower="-2.9670597283903604" upper="2.9670597283903604" velocity="2.443460952792061"/>
    <dynamics damping="10.0" friction="0.1"/>
  </joint>
  <link name="2_link_5">
    <inertial>
      <origin rpy="0 0 0" xyz="0.0 -0.029824 0.076267"/>
      <mass value="1.529239"/>
      <inertia ixx="0.008485" ixy="0.0" ixz="0.0" iyy="0.007136" iyz="0.002806" izz="0.003848"/>
    </inertial>
    <visual>
      <origin rpy="0 0 0" xyz="0.0 0.0 -0.9475"/>
      <geometry>
        <mesh filename="package://kuka_bord_description/meshes/iiwa7_meshes/visual/link_5.dae"/>
      </geometry>
    </visual>
    <collision>
      <origin rpy="0 0 0" xyz="0.0 0.0 -0.9475"/>
      <geometry>
        <mesh filename="package://kuka_bord_description/meshes/iiwa7_meshes/collision/link_5.stl"/>
      </geometry>
    </collision>
  </link>
  <joint name="2_A6" type="revolute">
    <origin rpy="0 0 0" xyz="0.0 -0.0707 0.1925"/>
    <parent link="2_link_5"/>
    <child link="2_link_6"/>
    <axis xyz="0.0 1.0 0.0"/>
    <limit effort="200" lower="-2.0943951023931953" upper="2.0943951023931953" velocity="3.141592653589793"/>
    <dynamics damping="10.0" friction="0.1"/>
  </joint>
  <link name="2_link_6">
    <inertial>
      <origin rpy="0 0 0" xyz="0.0 0.07102 0.00495"/>
      <mass value="2.403626"/>
      <inertia ixx="0.007067" ixy="0.0" ixz="0.0" iyy="0.006804" iyz="0.000311" izz="0.004629"/>
    </inertial>
    <visual>
      <origin rpy="0 0 0" xyz="0.0 0.0707 -1.14"/>
      <geometry>
        <mesh filename="package://kuka_bord_description/meshes/iiwa7_meshes/visual/link_6.dae"/>
      </geometry>
    </visual>
    <collision>
      <origin rpy="0 0 0" xyz="0.0 0.0707 -1.14"/>
      <geometry>
        <mesh filename="package://kuka_bord_description/meshes/iiwa7_meshes/collision/link_6.stl"/>
      </geometry>
    </collision>
  </link>
  <joint name="2_A7" type="revolute">
    <origin rpy="0 0 0" xyz="0.0 0.0707 0.091"/>
    <parent link="2_link_6"/>
    <child link="2_link_7"/>
    <axis xyz="0.0 0.0 1.0"/>
    <limit effort="200" lower="-3.0543261909900763" upper="3.0543261909900763" velocity="3.141592653589793"/>
    <dynamics damping="10.0" friction="0.1"/>
  </joint>
  <link name="2_link_7">
    <inertial>
      <origin rpy="0 0 0" xyz="3.0000e-06 -2.0000e-06 1.3782e-02"/>
      <mass value="0.259474"/>
      <inertia ixx="0.000171" ixy="0.0" ixz="0.0" iyy="0.000171" iyz="0.0" izz="0.000299"/>
    </inertial>
    <visual>
      <origin rpy="0 0 0" xyz="0.0 0.0 -1.231"/>
      <geometry>
        <mesh filename="package://kuka_bord_description/meshes/iiwa7_meshes/visual/link_7.dae"/>
      </geometry>
    </visual>
    <collision>
      <origin rpy="0 0 0" xyz="0.0 0.0 -1.231"/>
      <geometry>
        <mesh filename="package://kuka_bord_description/meshes/iiwa7_meshes/collision/link_7.stl"/>
      </geometry>
    </collision>
  </link>
  <joint name="2_joint_ee" type="fixed">
    <parent link="2_link_7"/>
    <child link="2_link_ee"/>
    <origin rpy="0 0 0" xyz="0 0 0.035"/>
  </joint>
  <link name="2_link_ee">
        </link>

  <!-- Joint between world and table-->
  <joint name="world_joint" type="fixed">
    <parent link="world"/>
    <child link="base_link"/>
  </joint>
  
  <!-- Joints between kukas and table -->
  <joint name="kuka_1_mount" type="fixed">
    <parent link="base_link"/>
    <child link="link_0"/>
    <origin xyz="0.273705 0.76 1.037203" rpy="0.785398163 0 -1.57079633"/>
  </joint>
   
  <joint name="kuka_2_mount" type="fixed">
    <parent link="base_link"/>
    <child link="2_link_0"/>
    <origin xyz="0.716295 0.76 1.037203" rpy="-0.785398163 0 -1.57079633"/>
  </joint>
   
</robot>
  
